<?xml version="1.0" encoding="utf-8"?>
<!-- =================================================================================== -->
<!-- |    This document was autogenerated by xacro from sawback.urdf.xacro             | -->
<!-- |    EDITING THIS FILE BY HAND IS NOT RECOMMENDED                                 | -->
<!-- =================================================================================== -->
<robot name="sawback">
  <material name="dark_grey">
    <color rgba="0.2 0.2 0.2 1.0"/>
  </material>
  <material name="light_grey">
    <color rgba="0.4 0.4 0.4 1.0"/>
  </material>
  <material name="red">
    <color rgba="0.8 0.0 0.0 1.0"/>
  </material>
  <material name="white">
    <color rgba="0.9 0.9 0.9 1.0"/>
  </material>
  <material name="yellow">
    <color rgba="0.8 0.8 0.0 1.0"/>
  </material>
  <material name="black">
    <color rgba="0.15 0.15 0.15 1.0"/>
  </material>
  <link name="front_rocker_link">
    <visual>
      <origin rpy="1.57079632679 0 1.57079632679" xyz="0 0 0"/>
      <geometry>
        <mesh filename="package://ridgeback_description/meshes/rocker.stl"/>
      </geometry>
      <material name="black"/>
    </visual>
    <inertial>
      <origin rpy="1.57079632679 0 1.57079632679" xyz="0 0 0"/>
      <mass value="10.267"/>
      <inertia ixx="0.0288" ixy="2.20484e-6" ixz="-1.3145e-5" iyy="0.4324" iyz="1.8944e-3" izz="0.4130"/>
    </inertial>
  </link>
  <joint name="front_rocker" type="revolute">
    <parent link="axle_link"/>
    <child link="front_rocker_link"/>
    <origin rpy="0 0 0" xyz="0.319 0 0"/>
    <axis xyz="1 0 0"/>
    <limit effort="0" lower="-0.08726" upper="0.08726" velocity="0"/>
  </joint>
  <link name="front_left_wheel_link">
    <visual>
      <origin rpy="1.57079632679 0 0" xyz="0 0 0"/>
      <geometry>
        <mesh filename="package://ridgeback_description/meshes/wheel.stl"/>
      </geometry>
      <material name="black"/>
    </visual>
    <collision>
      <origin rpy="1.57079632679 0 0" xyz="0 0 0"/>
      <geometry>
        <cylinder length="0.079" radius="0.0759"/>
      </geometry>
    </collision>
    <inertial>
      <origin rpy="0 0 0" xyz="0 0 0"/>
      <mass value="2.3"/>
      <inertia ixx="3.3212e-3" ixy="0" ixz="0" iyy="6.6424e-3" iyz="0" izz="3.3212e-3"/>
    </inertial>
  </link>
  <joint name="front_left_wheel" type="continuous">
    <parent link="front_rocker_link"/>
    <child link="front_left_wheel_link"/>
    <origin rpy="0 0 0" xyz="0 0.2755 0"/>
    <axis xyz="0 1 0"/>
  </joint>
  <transmission name="front_wheel_trans">
    <type>transmission_interface/SimpleTransmission</type>
    <joint name="front_left_wheel">
      <hardwareInterface>hardware_interface/VelocityJointInterface</hardwareInterface>
    </joint>
    <actuator name="front_left_actuator">
      <mechanicalReduction>1</mechanicalReduction>
    </actuator>
  </transmission>
  <link name="front_right_wheel_link">
    <visual>
      <origin rpy="1.57079632679 0 0" xyz="0 0 0"/>
      <geometry>
        <mesh filename="package://ridgeback_description/meshes/wheel.stl"/>
      </geometry>
      <material name="black"/>
    </visual>
    <collision>
      <origin rpy="1.57079632679 0 0" xyz="0 0 0"/>
      <geometry>
        <cylinder length="0.079" radius="0.0759"/>
      </geometry>
    </collision>
    <inertial>
      <origin rpy="0 0 0" xyz="0 0 0"/>
      <mass value="2.3"/>
      <inertia ixx="3.3212e-3" ixy="0" ixz="0" iyy="6.6424e-3" iyz="0" izz="3.3212e-3"/>
    </inertial>
  </link>
  <joint name="front_right_wheel" type="continuous">
    <parent link="front_rocker_link"/>
    <child link="front_right_wheel_link"/>
    <origin rpy="0 0 0" xyz="0 -0.2755 0"/>
    <axis xyz="0 1 0"/>
  </joint>
  <transmission name="front_wheel_trans">
    <type>transmission_interface/SimpleTransmission</type>
    <joint name="front_right_wheel">
      <hardwareInterface>hardware_interface/VelocityJointInterface</hardwareInterface>
    </joint>
    <actuator name="front_right_actuator">
      <mechanicalReduction>1</mechanicalReduction>
    </actuator>
  </transmission>
  <link name="rear_rocker_link">
    <visual>
      <origin rpy="1.57079632679 0 1.57079632679" xyz="0 0 0"/>
      <geometry>
        <mesh filename="package://ridgeback_description/meshes/rocker.stl"/>
      </geometry>
      <material name="black"/>
    </visual>
    <inertial>
      <origin rpy="1.57079632679 0 1.57079632679" xyz="0 0 0"/>
      <mass value="10.267"/>
      <inertia ixx="0.0288" ixy="2.20484e-6" ixz="-1.3145e-5" iyy="0.4324" iyz="1.8944e-3" izz="0.4130"/>
    </inertial>
  </link>
  <joint name="rear_rocker" type="fixed">
    <parent link="axle_link"/>
    <child link="rear_rocker_link"/>
    <origin rpy="0 0 0" xyz="-0.319 0 0"/>
    <axis xyz="1 0 0"/>
    <limit effort="0" velocity="0"/>
  </joint>
  <link name="rear_left_wheel_link">
    <visual>
      <origin rpy="1.57079632679 0 0" xyz="0 0 0"/>
      <geometry>
        <mesh filename="package://ridgeback_description/meshes/wheel.stl"/>
      </geometry>
      <material name="black"/>
    </visual>
    <collision>
      <origin rpy="1.57079632679 0 0" xyz="0 0 0"/>
      <geometry>
        <cylinder length="0.079" radius="0.0759"/>
      </geometry>
    </collision>
    <inertial>
      <origin rpy="0 0 0" xyz="0 0 0"/>
      <mass value="2.3"/>
      <inertia ixx="3.3212e-3" ixy="0" ixz="0" iyy="6.6424e-3" iyz="0" izz="3.3212e-3"/>
    </inertial>
  </link>
  <joint name="rear_left_wheel" type="continuous">
    <parent link="rear_rocker_link"/>
    <child link="rear_left_wheel_link"/>
    <origin rpy="0 0 0" xyz="0 0.2755 0"/>
    <axis xyz="0 1 0"/>
  </joint>
  <transmission name="rear_wheel_trans">
    <type>transmission_interface/SimpleTransmission</type>
    <joint name="rear_left_wheel">
      <hardwareInterface>hardware_interface/VelocityJointInterface</hardwareInterface>
    </joint>
    <actuator name="rear_left_actuator">
      <mechanicalReduction>1</mechanicalReduction>
    </actuator>
  </transmission>
  <link name="rear_right_wheel_link">
    <visual>
      <origin rpy="1.57079632679 0 0" xyz="0 0 0"/>
      <geometry>
        <mesh filename="package://ridgeback_description/meshes/wheel.stl"/>
      </geometry>
      <material name="black"/>
    </visual>
    <collision>
      <origin rpy="1.57079632679 0 0" xyz="0 0 0"/>
      <geometry>
        <cylinder length="0.079" radius="0.0759"/>
      </geometry>
    </collision>
    <inertial>
      <origin rpy="0 0 0" xyz="0 0 0"/>
      <mass value="2.3"/>
      <inertia ixx="3.3212e-3" ixy="0" ixz="0" iyy="6.6424e-3" iyz="0" izz="3.3212e-3"/>
    </inertial>
  </link>
  <joint name="rear_right_wheel" type="continuous">
    <parent link="rear_rocker_link"/>
    <child link="rear_right_wheel_link"/>
    <origin rpy="0 0 0" xyz="0 -0.2755 0"/>
    <axis xyz="0 1 0"/>
  </joint>
  <transmission name="rear_wheel_trans">
    <type>transmission_interface/SimpleTransmission</type>
    <joint name="rear_right_wheel">
      <hardwareInterface>hardware_interface/VelocityJointInterface</hardwareInterface>
    </joint>
    <actuator name="rear_right_actuator">
      <mechanicalReduction>1</mechanicalReduction>
    </actuator>
  </transmission>
  <link name="base_link"/>
  <joint name="base_link_joint" type="fixed">
    <origin rpy="0 0 0" xyz="0 0 0"/>
    <parent link="base_link"/>
    <child link="chassis_link"/>
  </joint>
  <link name="chassis_link">
    <visual>
      <origin rpy="0 0 0" xyz="0 0 0"/>
      <geometry>
        <mesh filename="package://ridgeback_description/meshes/body.stl"/>
      </geometry>
      <material name="black"/>
    </visual>
    <collision>
      <origin xyz="0 0 0"/>
      <geometry>
        <mesh filename="package://ridgeback_description/meshes/body-collision.stl"/>
      </geometry>
    </collision>
    <inertial>
      <origin rpy="1.57079632679 0 1.57079632679" xyz="0.012 0.002 0.067"/>
      <mass value="165.304"/>
      <inertia ixx="4.4744" ixy="0.03098" ixz="0.003647" iyy="7.1624" iyz="0.1228" izz="4.6155"/>
    </inertial>
  </link>
  <joint name="right_side_cover_link_joint" type="fixed">
    <origin rpy="0 0 0" xyz="0 0 0"/>
    <parent link="chassis_link"/>
    <child link="right_side_cover_link"/>
  </joint>
  <joint name="left_side_cover_link_joint" type="fixed">
    <origin rpy="0 0 0" xyz="0 0 0"/>
    <parent link="chassis_link"/>
    <child link="left_side_cover_link"/>
  </joint>
  <link name="left_side_cover_link">
    <visual>
      <origin rpy="0 0 3.14159265359" xyz="0 0 0"/>
      <geometry>
        <mesh filename="package://ridgeback_description/meshes/side-cover.stl"/>
      </geometry>
      <material name="yellow"/>
    </visual>
  </link>
  <link name="right_side_cover_link">
    <visual>
      <origin rpy="0 0 0" xyz="0 0 0"/>
      <geometry>
        <mesh filename="package://ridgeback_description/meshes/side-cover.stl"/>
      </geometry>
      <material name="yellow"/>
    </visual>
  </link>
  <joint name="front_cover_link_joint" type="fixed">
    <origin rpy="0 0 0" xyz="0 0 0"/>
    <parent link="chassis_link"/>
    <child link="front_cover_link"/>
  </joint>
  <link name="front_cover_link">
    <visual>
      <origin rpy="0 0 0" xyz="0 0 0"/>
      <geometry>
        <mesh filename="package://ridgeback_description/meshes/end-cover.stl"/>
      </geometry>
      <material name="black"/>
    </visual>
  </link>
  <joint name="rear_cover_link_joint" type="fixed">
    <origin rpy="0 0 0" xyz="0 0 0"/>
    <parent link="chassis_link"/>
    <child link="rear_cover_link"/>
  </joint>
  <link name="rear_cover_link">
    <visual>
      <origin rpy="0 0 3.14159265359" xyz="0 0 0"/>
      <geometry>
        <mesh filename="package://ridgeback_description/meshes/end-cover.stl"/>
      </geometry>
      <material name="black"/>
    </visual>
  </link>
  <joint name="front_lights_link_joint" type="fixed">
    <origin rpy="0 0 0" xyz="0 0 0"/>
    <parent link="chassis_link"/>
    <child link="front_lights_link"/>
  </joint>
  <joint name="rear_lights_link_joint" type="fixed">
    <origin rpy="0 0 0" xyz="0 0 0"/>
    <parent link="chassis_link"/>
    <child link="rear_lights_link"/>
  </joint>
  <link name="front_lights_link">
    <visual>
      <origin rpy="0 0 0" xyz="0 0 0"/>
      <geometry>
        <mesh filename="package://ridgeback_description/meshes/lights.stl"/>
      </geometry>
      <material name="white"/>
    </visual>
  </link>
  <link name="rear_lights_link">
    <visual>
      <origin rpy="0 0 3.14159265359" xyz="0 0 0"/>
      <geometry>
        <mesh filename="package://ridgeback_description/meshes/lights.stl"/>
      </geometry>
      <material name="red"/>
    </visual>
  </link>
  <joint name="top_link_joint" type="fixed">
    <origin rpy="0 0 0" xyz="0 0 0"/>
    <parent link="chassis_link"/>
    <child link="top_link"/>
  </joint>
  <link name="top_link">
    <visual>
      <origin rpy="0 0 0" xyz="0 0 0"/>
      <geometry>
        <mesh filename="package://ridgeback_description/meshes/top.stl"/>
      </geometry>
      <material name="black"/>
    </visual>
    <collision>
      <origin rpy="0 0 0" xyz="0 0 0"/>
      <geometry>
        <mesh filename="package://ridgeback_description/meshes/top.stl"/>
      </geometry>
    </collision>
  </link>
  <joint name="axle_joint" type="fixed">
    <origin rpy="0 0 0" xyz="0 0 0.05"/>
    <parent link="chassis_link"/>
    <child link="axle_link"/>
  </joint>
  <link name="axle_link">
    <visual>
      <origin rpy="0 1.57079632679 0" xyz="0 0 0"/>
      <geometry>
        <mesh filename="package://ridgeback_description/meshes/axle.stl"/>
      </geometry>
      <material name="black"/>
    </visual>
  </link>
  <link name="imu_link">
    <inertial>
      <mass value="0.001"/>
      <origin rpy="0 0 0" xyz="0 0 0"/>
      <inertia ixx="1e-09" ixy="0.0" ixz="0.0" iyy="1e-09" iyz="0.0" izz="1e-09"/>
    </inertial>
  </link>
  <joint name="imu_joint" type="fixed">
    <parent link="chassis_link"/>
    <child link="imu_link"/>
    <origin rpy="0 0 0" xyz="0.2085 -0.2902 0.1681"/>
  </joint>
  <link name="mid_mount"/>
  <joint name="mid_mount_joint" type="fixed">
    <parent link="base_link"/>
    <child link="mid_mount"/>
    <origin rpy="0 0 0" xyz="0 0 0.28"/>
  </joint>
  <gazebo>
    <plugin filename="libgazebo_ros_control.so" name="gazebo_ros_control">
      <robotNamespace>/</robotNamespace>
    </plugin>
    <plugin filename="libridgeback_ros_force_based_move.so" name="ridgeback_ros_force_based_move">
      <robotNamespace>/</robotNamespace>
      <commandTopic>cmd_vel</commandTopic>
      <odometryTopic>odom</odometryTopic>
      <odometryFrame>odom</odometryFrame>
      <odometryRate>25.0</odometryRate>
      <robotBaseFrame>base_link</robotBaseFrame>
      <cmdVelTimeOut>0.25</cmdVelTimeOut>
      <!-- Don't publish a transform: the controller does it. -->
      <publishOdometryTf>0</publishOdometryTf>
      <yaw_velocity_p_gain>500.0</yaw_velocity_p_gain>
      <x_velocity_p_gain>10000.0</x_velocity_p_gain>
      <y_velocity_p_gain>10000.0</y_velocity_p_gain>
    </plugin>
    <plugin filename="libhector_gazebo_ros_imu.so" name="imu_controller">
      <robotNamespace>/</robotNamespace>
      <updateRate>50.0</updateRate>
      <bodyName>imu_link</bodyName>
      <topicName>imu/data</topicName>
      <frameId>base_link</frameId>
      <accelDrift>0.005 0.005 0.005</accelDrift>
      <accelGaussianNoise>0.005 0.005 0.005</accelGaussianNoise>
      <rateDrift>0.00005 0.00005 0.00005</rateDrift>
      <rateGaussianNoise>0.00005 0.00005 0.00005</rateGaussianNoise>
      <headingDrift>0.005</headingDrift>
      <headingGaussianNoise>0.005</headingGaussianNoise>
    </plugin>
    <plugin filename="libgazebo_ros_joint_state_publisher.so" name="gazebo_ros_joint_state_publisher">
      <jointName>front_rocker</jointName>
      <robotNamespace>/</robotNamespace>
      <updateRate>50.0</updateRate>
    </plugin>
  </gazebo>
  <!-- All static links get collapsed down to base_link in Gazebo, so that's
       the one to apply the colour to (in Gazebo 5+). -->
  <gazebo reference="base_link">
    <material>Gazebo/DarkGrey</material>
    <gravity>true</gravity>
  </gazebo>
  <!-- Individual link colouring still needed in Gazebo 2.x -->
  <gazebo reference="chassis_link">
    <material>Gazebo/DarkGrey</material>
  </gazebo>
  <gazebo reference="top_link">
    <material>Gazebo/DarkGrey</material>
  </gazebo>
  <gazebo reference="left_side_cover_link">
    <material>Gazebo/Yellow</material>
  </gazebo>
  <gazebo reference="right_side_cover_link">
    <material>Gazebo/Yellow</material>
  </gazebo>
  <gazebo reference="front_cover_link">
    <material>Gazebo/DarkGrey</material>
  </gazebo>
  <gazebo reference="rear_cover_link">
    <material>Gazebo/DarkGrey</material>
  </gazebo>
  <gazebo reference="front_lights_link">
    <material>Gazebo/White</material>
  </gazebo>
  <gazebo reference="rear_lights_link">
    <material>Gazebo/Red</material>
  </gazebo>
  <gazebo reference="front_rocker_link">
    <material>Gazebo/DarkGrey</material>
  </gazebo>
  <gazebo reference="rear_rocker_link">
    <material>Gazebo/DarkGrey</material>
  </gazebo>
  <gazebo reference="axle_link">
    <material>Gazebo/DarkGrey</material>
  </gazebo>
  <!-- Wheel friction to zero, as movement is handled by applying forces at
       the body level. -->
  <gazebo reference="front_left_wheel_link">
    <material>Gazebo/DarkGrey</material>
    <mu1>0.0</mu1>
    <mu2>0.0</mu2>
  </gazebo>
  <gazebo reference="front_right_wheel_link">
    <material>Gazebo/DarkGrey</material>
    <mu1>0.0</mu1>
    <mu2>0.0</mu2>
  </gazebo>
  <gazebo reference="rear_left_wheel_link">
    <material>Gazebo/DarkGrey</material>
    <mu1>0.0</mu1>
    <mu2>0.0</mu2>
  </gazebo>
  <gazebo reference="rear_right_wheel_link">
    <material>Gazebo/DarkGrey</material>
    <mu1>0.0</mu1>
    <mu2>0.0</mu2>
  </gazebo>
  <!-- This is an wheel-level solution to possibly revisit at a future date. -->
  <!--<gazebo>
    <plugin name="mecanum_gazebo" filename="libmecanum_force_plugin.so">
      <wheelJointName>front_left_wheel</wheelJointName>
      <forceScaleFactor>1</forceScaleFactor>
    </plugin>
    <plugin name="mecanum_gazebo" filename="libmecanum_force_plugin.so">
      <wheelJointName>front_right_wheel</wheelJointName>
      <forceScaleFactor>-1</forceScaleFactor>
    </plugin>
    <plugin name="mecanum_gazebo" filename="libmecanum_force_plugin.so">
      <wheelJointName>rear_left_wheel</wheelJointName>
      <forceScaleFactor>-1</forceScaleFactor>
    </plugin>
    <plugin name="mecanum_gazebo" filename="libmecanum_force_plugin.so">
      <wheelJointName>rear_right_wheel</wheelJointName>
      <forceScaleFactor>1</forceScaleFactor>
    </plugin>
  </gazebo> -->
  <!--
    As you add to this URDF, please be aware that both the robot and
    simulation include it. You must retain compatibility with all of
    the following launch files:

    ridgeback_viz/launch/view_model.launch
    ridgeback_gazebo/launch/ridgeback_world.launch
    ridgeback_base/launch/base.launch
  -->
  <!-- This file is a placeholder which is included by default from
       ridgeback.urdf.xacro. If a robot is being customized and requires
       additional URDF, set the RIDGEBACK_URDF_EXTRAS environment variable
       to the full path of the file you would like included. -->
  <!-- Add a box to represent the controller -->
  <link name="controller_enclosure">
    <visual>
      <origin rpy="0 0 0" xyz="0 0 0"/>
      <geometry>
        <box size="0.209 0.352 0.537"/>
      </geometry>
      <material name="grey">
        <color rgba="0.2 0.2 0.2 1"/>
      </material>
    </visual>
    <collision>
      <origin rpy="0 0 0" xyz="0 0 0"/>
      <geometry>
        <box size="0.209 0.352 0.537"/>
      </geometry>
    </collision>
  </link>
  <joint name="base_to_controller_enclosure" type="fixed">
    <parent link="mid_mount"/>
    <child link="controller_enclosure"/>
    <origin xyz="-0.285 0 0.268"/>
  </joint>
  <!-- Create link for VLP16 mesh -->
  <link name="velodyne_mesh">
    <visual>
      <geometry>
        <mesh filename="package://sawback_description/meshes/vlp16_assy.stl"/>
      </geometry>
      <material name="light_grey">
        <color rgba="0.4 0.4 0.4 1"/>
      </material>
    </visual>
    <collision>
      <geometry>
        <mesh filename="package://sawback_description/meshes/vlp16_assy.stl"/>
      </geometry>
    </collision>
  </link>
  <joint name="base_to_lidar_mesh" type="fixed">
    <parent link="mid_mount"/>
    <child link="velodyne_mesh"/>
    <origin rpy="0 0 0" xyz="0.365 0 0"/>
  </joint>
  <!-- Create a link between the VLP16 mesh and sensor origin -->
  <link name="velodyne"/>
  <joint name="vlp16_mesh_to_vlp16_origin" type="fixed">
    <parent link="velodyne_mesh"/>
    <child link="velodyne"/>
    <origin rpy="0 0 0" xyz="0 0 0.195"/>
  </joint>
  <!-- Create link for Bumblebee mesh -->
  <link name="bb2_mesh">
    <visual>
      <geometry>
        <mesh filename="package://sawback_description/meshes/bb2_stereo_cam.dae"/>
      </geometry>
    </visual>
  </link>
  <joint name="base_to_bb2_mesh" type="fixed">
    <parent link="mid_mount"/>
    <child link="bb2_mesh"/>
    <origin rpy="0 0 1.5708" xyz="0.43 0 0"/>
  </joint>
  <!-- Create a link between the BB2 mesh and sensor origin -->
  <link name="bumblebee"/>
  <joint name="bb2_mesh_to_bb2_origin" type="fixed">
    <parent link="bb2_mesh"/>
    <child link="bumblebee"/>
    <origin rpy="0 0 0" xyz="0.001 0 0.07"/>
  </joint>
  <joint name="front_laser_joint" type="fixed">
    <origin rpy="0 0 0.0" xyz="0.3932 0 0.2330"/>
    <parent link="chassis_link"/>
    <child link="front_laser"/>
  </joint>
  <link name="front_laser">
    <inertial>
      <mass value="0.130"/>
      <origin xyz="0 0 0"/>
      <inertia ixx="8.01666346e-05" ixy="0.0" ixz="0.0" iyy="8.01666346e-05" iyz="0.0" izz="5.4166645e-05"/>
    </inertial>
    <visual>
      <origin rpy="0 0 0" xyz="0 0 0"/>
      <geometry>
        <!-- Origin of this mesh is the focal point of the LIDAR. -->
        <mesh filename="package://ridgeback_description/meshes/ust-10lx.stl"/>
      </geometry>
      <material name="dark_grey"/>
    </visual>
    <collision>
      <origin rpy="0 0 0" xyz="0 0 -0.0122"/>
      <geometry>
        <box size="0.05 0.05 0.07"/>
      </geometry>
    </collision>
  </link>
  <gazebo reference="front_laser">
    <turnGravityOff>false</turnGravityOff>
    <sensor name="front_laser" type="ray">
      <pose>0 0 0 0 0 0</pose>
      <visualize>false</visualize>
      <update_rate>50</update_rate>
      <ray>
        <scan>
          <horizontal>
            <samples>720</samples>
            <resolution>1</resolution>
            <min_angle>-2.35619</min_angle>
            <max_angle>2.35619</max_angle>
          </horizontal>
        </scan>
        <range>
          <min>0.20</min>
          <max>10.0</max>
          <resolution>0.01</resolution>
        </range>
        <noise>
          <type>gaussian</type>
          <mean>0.0</mean>
          <stddev>0.001</stddev>
        </noise>
      </ray>
      <plugin filename="libgazebo_ros_laser.so" name="gazebo_ros_laser">
        <topicName>front/scan</topicName>
        <frameName>front_laser</frameName>
        <hokuyoMinIntensity>101</hokuyoMinIntensity>
      </plugin>
    </sensor>
    <material>Gazebo/DarkGrey</material>
  </gazebo>
  <joint name="rear_laser_joint" type="fixed">
    <origin rpy="0 0 3.14159265359" xyz="-0.3932 0 0.2330"/>
    <parent link="chassis_link"/>
    <child link="rear_laser"/>
  </joint>
  <link name="rear_laser">
    <inertial>
      <mass value="0.130"/>
      <origin xyz="0 0 0"/>
      <inertia ixx="8.01666346e-05" ixy="0.0" ixz="0.0" iyy="8.01666346e-05" iyz="0.0" izz="5.4166645e-05"/>
    </inertial>
    <visual>
      <origin rpy="0 0 0" xyz="0 0 0"/>
      <geometry>
        <!-- Origin of this mesh is the focal point of the LIDAR. -->
        <mesh filename="package://ridgeback_description/meshes/ust-10lx.stl"/>
      </geometry>
      <material name="dark_grey"/>
    </visual>
    <collision>
      <origin rpy="0 0 0" xyz="0 0 -0.0122"/>
      <geometry>
        <box size="0.05 0.05 0.07"/>
      </geometry>
    </collision>
  </link>
  <gazebo reference="rear_laser">
    <turnGravityOff>false</turnGravityOff>
    <sensor name="rear_laser" type="ray">
      <pose>0 0 0 0 0 0</pose>
      <visualize>false</visualize>
      <update_rate>50</update_rate>
      <ray>
        <scan>
          <horizontal>
            <samples>720</samples>
            <resolution>1</resolution>
            <min_angle>-2.35619</min_angle>
            <max_angle>2.35619</max_angle>
          </horizontal>
        </scan>
        <range>
          <min>0.20</min>
          <max>10.0</max>
          <resolution>0.01</resolution>
        </range>
        <noise>
          <type>gaussian</type>
          <mean>0.0</mean>
          <stddev>0.001</stddev>
        </noise>
      </ray>
      <plugin filename="libgazebo_ros_laser.so" name="gazebo_ros_laser">
        <topicName>rear/scan</topicName>
        <frameName>rear_laser</frameName>
        <hokuyoMinIntensity>101</hokuyoMinIntensity>
      </plugin>
    </sensor>
    <material>Gazebo/DarkGrey</material>
  </gazebo>
  <material name="basic_black">
    <color rgba="0 0 0 1"/>
  </material>
  <material name="darkgray">
    <color rgba=".2 .2 .2 1"/>
  </material>
  <material name="darkred">
    <color rgba=".5 .1 .1 1"/>
  </material>
  <material name="sawyer_red">
    <color rgba=".5 .1 .1 1"/>
  </material>
  <material name="sawyer_gray">
    <color rgba="0.75294 0.75294 0.75294 1"/>
  </material>
  <link name="base"/>
  <link name="torso">
    <visual>
      <origin rpy="0 0 0" xyz="0 0 0"/>
      <geometry>
        <box size="0.001 0.001 0.001"/>
      </geometry>
      <material name="darkgray">
        <color rgba=".2 .2 .2 1"/>
      </material>
    </visual>
  </link>
  <joint name="right_arm_mount" type="fixed">
    <origin rpy="0 0 0" xyz="0.0 0.0 0.0"/>
    <parent link="base"/>
    <child link="right_arm_base_link"/>
  </joint>
  <joint name="torso_t0" type="fixed">
    <origin rpy="0 0 0" xyz="0 0 0"/>
    <parent link="base"/>
    <child link="torso"/>
  </joint>
  <link name="right_arm_base_link">
    <inertial>
      <origin rpy="0 0 0" xyz="-0.0006241 -2.8025E-05 0.065404"/>
      <mass value="2.0687"/>
      <inertia ixx="0.0067599" ixy="-4.2024E-05" ixz="-6.1904E-07" iyy="0.0067877" iyz="1.5888E-05" izz="0.0074031"/>
    </inertial>
    <visual>
      <origin rpy="0 0 0" xyz="0 0 0"/>
      <geometry>
        <mesh filename="package://sawyer_description/meshes/sawyer_pv/base.DAE"/>
      </geometry>
      <material name="sawyer_red"/>
    </visual>
    <collision>
      <origin rpy="0 0 0" xyz="0 0 0.12"/>
      <geometry>
        <cylinder length="0.24" radius="0.08"/>
      </geometry>
    </collision>
  </link>
  <link name="right_l0">
    <inertial>
      <origin rpy="0 0 0" xyz="0.024366 0.010969 0.14363"/>
      <mass value="5.3213"/>
      <inertia ixx="0.053314" ixy="0.0047093" ixz="0.011734" iyy="0.057902" iyz="0.0080179" izz="0.023659"/>
    </inertial>
    <visual>
      <origin rpy="0 0 0" xyz="0 0 0"/>
      <geometry>
        <mesh filename="package://sawyer_description/meshes/sawyer_mp3/l0.DAE"/>
      </geometry>
      <material name="sawyer_red"/>
    </visual>
    <collision>
      <origin rpy="0 0 0" xyz="0.08 0 0.23"/>
      <geometry>
        <sphere radius="0.07"/>
      </geometry>
    </collision>
  </link>
  <joint name="right_j0" type="revolute">
    <origin rpy="0 0 0" xyz="0 0 0.08"/>
    <parent link="right_arm_base_link"/>
    <child link="right_l0"/>
    <axis xyz="0 0 1"/>
    <limit effort="80.0" lower="-3.0503" upper="3.0503" velocity="1.74"/>
    <dynamics damping="10.0" friction="5.0"/>
  </joint>
  <link name="head">
    <inertial>
      <origin rpy="0 0 0" xyz="0.0053207 -2.6549E-05 0.1021"/>
      <mass value="1.5795"/>
      <inertia ixx="0.011833" ixy="-4.4669E-06" ixz="4.9425E-05" iyy="0.0082709" iyz="4.2124E-07" izz="0.0049661"/>
    </inertial>
    <visual>
      <origin rpy="0 0 0" xyz="0 0 0"/>
      <geometry>
        <mesh filename="package://sawyer_description/meshes/sawyer_pv/head.DAE"/>
      </geometry>
      <material name="sawyer_red"/>
    </visual>
    <collision>
      <origin rpy="0 0 0" xyz="0 0 0.08"/>
      <geometry>
        <sphere radius="0.18"/>
      </geometry>
    </collision>
  </link>
  <joint name="head_pan" type="revolute">
    <origin rpy="0 0 0" xyz="0 0 0.2965"/>
    <parent link="right_l0"/>
    <child link="head"/>
    <axis xyz="0 0 1"/>
    <limit effort="8" lower="-5.0952" upper="0.9064" velocity="1.8"/>
    <dynamics damping="1.0" friction="0.5"/>
  </joint>
  <link name="right_torso_itb">
  </link>
  <joint name="right_torso_itb" type="fixed">
    <origin rpy="0 -1.57079632679 0" xyz="-.055 0 .22"/>
    <parent link="right_l0"/>
    <child link="right_torso_itb"/>
    <axis xyz="0 0 1"/>
  </joint>
  <link name="right_l1">
    <inertial>
      <origin rpy="0 0 0" xyz="-0.0030849 -0.026811 0.092521"/>
      <mass value="4.505"/>
      <inertia ixx="0.022398" ixy="-0.00023986" ixz="-0.00029362" iyy="0.014613" iyz="-0.0060875" izz="0.017295"/>
    </inertial>
    <visual>
      <origin rpy="0 0 0" xyz="0 0 0"/>
      <geometry>
        <mesh filename="package://sawyer_description/meshes/sawyer_mp3/l1.DAE"/>
      </geometry>
      <material name="sawyer_red"/>
    </visual>
    <collision>
      <origin rpy="0 0 0" xyz="0 0 0.1225"/>
      <geometry>
        <sphere radius="0.07"/>
      </geometry>
    </collision>
  </link>
  <joint name="right_j1" type="revolute">
    <origin rpy="-1.57079632679 1.57079632679 0" xyz="0.081 0.05 0.237"/>
    <parent link="right_l0"/>
    <child link="right_l1"/>
    <axis xyz="0 0 1"/>
    <limit effort="80.0" lower="-3.8095" upper="2.2736" velocity="1.328"/>
    <dynamics damping="5.0" friction="2.0"/>
  </joint>
  <link name="right_l2">
    <inertial>
      <origin rpy="0 0 0" xyz="-0.00016044 -0.014967 0.13582"/>
      <mass value="1.745"/>
      <inertia ixx="0.025506" ixy="4.4101E-06" ixz="1.4955E-05" iyy="0.0253" iyz="-0.0033204" izz="0.0034179"/>
    </inertial>
    <visual>
      <origin rpy="0 0 0" xyz="0 0 0"/>
      <geometry>
        <mesh filename="package://sawyer_description/meshes/sawyer_pv/l2.DAE"/>
      </geometry>
      <material name="sawyer_red"/>
    </visual>
    <collision>
      <origin rpy="0 0 0" xyz="0 0 0.08"/>
      <geometry>
        <cylinder length="0.34" radius="0.06"/>
      </geometry>
    </collision>
  </link>
  <joint name="right_j2" type="revolute">
    <origin rpy="1.57079632679 0 0" xyz="0 -0.14 0.1425"/>
    <parent link="right_l1"/>
    <child link="right_l2"/>
    <axis xyz="0 0 1"/>
    <limit effort="40.0" lower="-3.0426" upper="3.0426" velocity="1.957"/>
    <dynamics damping="5.0" friction="2.0"/>
  </joint>
  <link name="right_l3">
    <inertial>
      <origin rpy="0 0 0" xyz="-0.0048135 -0.0281 -0.084154"/>
      <mass value="2.5097"/>
      <inertia ixx="0.01016" ixy="-9.7452E-06" ixz="0.00026624" iyy="0.0065685" iyz="0.0030316" izz="0.0069078"/>
    </inertial>
    <visual>
      <origin rpy="0 0 0" xyz="0 0 0"/>
      <geometry>
        <mesh filename="package://sawyer_description/meshes/sawyer_pv/l3.DAE"/>
      </geometry>
      <material name="sawyer_red"/>
    </visual>
    <collision>
      <origin rpy="0 0 0" xyz="0 -0.01 -0.12"/>
      <geometry>
        <sphere radius="0.06"/>
      </geometry>
    </collision>
  </link>
  <joint name="right_j3" type="revolute">
    <origin rpy="-1.57079632679 0 0" xyz="0 -0.042 0.26"/>
    <parent link="right_l2"/>
    <child link="right_l3"/>
    <axis xyz="0 0 1"/>
    <limit effort="40.0" lower="-3.0439" upper="3.0439" velocity="1.957"/>
    <dynamics damping="1.0" friction="0.5"/>
  </joint>
  <link name="right_l4">
    <inertial>
      <origin rpy="0 0 0" xyz="-0.0018844 0.0069001 0.1341"/>
      <mass value="1.1136"/>
      <inertia ixx="0.013557" ixy="1.8109E-05" ixz="0.00013523" iyy="0.013555" iyz="0.0010561" izz="0.0013658"/>
    </inertial>
    <visual>
      <origin rpy="0 0 0" xyz="0 0 0"/>
      <geometry>
        <mesh filename="package://sawyer_description/meshes/sawyer_pv/l4.DAE"/>
      </geometry>
      <material name="sawyer_red"/>
    </visual>
    <collision>
      <origin rpy="0 0 0" xyz="0 0 0.11"/>
      <geometry>
        <cylinder length="0.30" radius="0.045"/>
      </geometry>
    </collision>
  </link>
  <joint name="right_j4" type="revolute">
    <origin rpy="1.57079632679 0 0" xyz="0 -0.125 -0.1265"/>
    <parent link="right_l3"/>
    <child link="right_l4"/>
    <axis xyz="0 0 1"/>
    <limit effort="9.0" lower="-2.9761" upper="2.9761" velocity="3.485"/>
    <dynamics damping="2.0" friction="1.0"/>
  </joint>
  <link name="right_arm_itb">
  </link>
  <joint name="right_arm_itb" type="fixed">
    <origin rpy="0 -1.57079632679 0" xyz="-.055 0 .075"/>
    <parent link="right_l4"/>
    <child link="right_arm_itb"/>
    <axis xyz="0 0 1"/>
  </joint>
  <link name="right_l5">
    <inertial>
      <origin rpy="0 0 0" xyz="0.0061133 -0.023697 0.076416"/>
      <mass value="1.5625"/>
      <inertia ixx="0.0047328" ixy="0.00011526" ixz="4.6269E-05" iyy="0.0029676" iyz="-0.0011557" izz="0.0031762"/>
    </inertial>
    <visual>
      <origin rpy="0 0 0" xyz="0 0 0"/>
      <geometry>
        <mesh filename="package://sawyer_description/meshes/sawyer_pv/l5.DAE"/>
      </geometry>
      <material name="sawyer_red"/>
    </visual>
    <collision>
      <origin rpy="0 0 0" xyz="0 0 0.1"/>
      <geometry>
        <sphere radius="0.06"/>
      </geometry>
    </collision>
  </link>
  <joint name="right_j5" type="revolute">
    <origin rpy="-1.57079632679 0 0" xyz="0 0.031 0.275"/>
    <parent link="right_l4"/>
    <child link="right_l5"/>
    <axis xyz="0 0 1"/>
    <limit effort="9.0" lower="-2.9761" upper="2.9761" velocity="3.485"/>
    <dynamics damping="1.0" friction="0.5"/>
  </joint>
  <link name="right_hand_camera"/>
  <joint name="right_hand_camera" type="fixed">
    <origin rpy="0 1.57079632679 0" xyz="0.039552 -0.033 0.0695"/>
    <parent link="right_l5"/>
    <child link="right_hand_camera"/>
    <axis xyz="0 0 0"/>
  </joint>
  <link name="right_wrist"/>
  <joint name="right_wrist" type="fixed">
    <origin rpy="1.57079632679 0 0" xyz="0 0 0.10541"/>
    <parent link="right_l5"/>
    <child link="right_wrist"/>
    <axis xyz="0 0 0"/>
  </joint>
  <link name="right_l6">
    <inertial>
      <origin rpy="0 0 0" xyz="-8.0726E-06 0.0085838 -0.0049566"/>
      <mass value="0.3292"/>
      <inertia ixx="0.00031105" ixy="1.4771E-06" ixz="-3.7074E-07" iyy="0.00021549" iyz="-8.4533E-06" izz="0.00035976"/>
    </inertial>
    <visual>
      <origin rpy="0 0 0" xyz="0 0 0"/>
      <geometry>
        <mesh filename="package://sawyer_description/meshes/sawyer_mp1/l6.DAE"/>
      </geometry>
      <material name="sawyer_red"/>
    </visual>
    <collision>
      <origin rpy="0 0 0" xyz="0 0.015 -0.01"/>
      <geometry>
        <cylinder length="0.05" radius="0.055"/>
      </geometry>
    </collision>
  </link>
  <joint name="right_j6" type="revolute">
    <origin rpy="-1.57079632679 -0.17453 3.1416" xyz="0 -0.11 0.1053"/>
    <parent link="right_l5"/>
    <child link="right_l6"/>
    <axis xyz="0 0 1"/>
    <limit effort="9.0" lower="-3.14" upper="3.14" velocity="4.545"/>
    <dynamics damping="1.0" friction="0.5"/>
  </joint>
  <link name="right_hand">
    <collision>
      <origin rpy="0 0 0" xyz="0 0 0.02"/>
      <geometry>
        <cylinder length="0.03" radius="0.035"/>
      </geometry>
    </collision>
    <inertial>
      <origin rpy="0 0 0" xyz="0 0.1 0"/>
      <mass value="0.01"/>
      <inertia ixx="0.01" ixy="0.01" ixz="0.01" iyy="0.01" iyz="0.01" izz="0.01"/>
    </inertial>
  </link>
  <joint name="right_hand" type="fixed">
    <origin rpy="0 0 1.570796" xyz="0 0 0.0245"/>
    <axis xyz="0 0 1"/>
    <parent link="right_l6"/>
    <child link="right_hand"/>
  </joint>
  <link name="right_l1_2">
    <collision>
      <origin rpy="0 0 0" xyz="0 0 0.035"/>
      <geometry>
        <cylinder length="0.14" radius="0.07"/>
      </geometry>
    </collision>
  </link>
  <joint name="right_j1_2" type="fixed">
    <origin rpy="0 0 0" xyz="0 0 0"/>
    <parent link="right_l1"/>
    <child link="right_l1_2"/>
    <axis xyz="0 0 1"/>
  </joint>
  <link name="right_l2_2">
    <collision>
      <origin rpy="0 0 0" xyz="0 0 0.26"/>
      <geometry>
        <sphere radius="0.06"/>
      </geometry>
    </collision>
  </link>
  <joint name="right_j2_2" type="fixed">
    <origin rpy="0 0 0" xyz="0 0 0"/>
    <parent link="right_l2"/>
    <child link="right_l2_2"/>
    <axis xyz="0 0 1"/>
  </joint>
  <link name="right_l4_2">
    <collision>
      <origin rpy="0 0 0" xyz="0 0.01 0.26"/>
      <geometry>
        <sphere radius="0.06"/>
      </geometry>
    </collision>
  </link>
  <joint name="right_j4_2" type="fixed">
    <origin rpy="0 0 0" xyz="0 0 0"/>
    <parent link="right_l4"/>
    <child link="right_l4_2"/>
    <axis xyz="0 0 1"/>
  </joint>
  <link name="screen">
    <visual>
      <origin rpy="0 0 0" xyz="0 0 0"/>
      <geometry>
        <box size="0.24 0.14 0.002"/>
      </geometry>
      <material name="darkgray"/>
    </visual>
    <collision>
      <origin rpy="0 0 0" xyz="0 0 0"/>
      <geometry>
        <sphere radius="0.001"/>
      </geometry>
    </collision>
  </link>
  <joint name="display_joint" type="fixed">
    <origin rpy="1.57079632679 0 1.57079632679" xyz="0.03 0.0 0.105"/>
    <parent link="head"/>
    <child link="screen"/>
  </joint>
  <link name="head_camera"/>
  <joint name="head_camera" type="fixed">
    <origin rpy="-2.1293 0 -1.57079632679" xyz="0.0228027 0 0.216572"/>
    <parent link="head"/>
    <child link="head_camera"/>
    <axis xyz="0 0 0"/>
  </joint>
  <!-- Base of whole end effector - (Connector Plate + Electric Gripper + Fingers + Tips) -->
  <link name="right_gripper_base">
    <inertial>
      <!-- Sum Gripper Mass - for whole end effector, measured from end of plastic cuff -->
      <mass value="0.47"/>
      <origin rpy="0 0 0" xyz="0.0028 -0.0004 0.0343"/>
      <inertia ixx="1e-08" ixy="0" ixz="0" iyy="1e-08" iyz="0" izz="1e-08"/>
    </inertial>
  </link>
  <!-- Electric Gripper Base Link -->
  <link name="right_electric_gripper_base">
    <visual>
      <origin rpy="0 0 0" xyz="0 0 0"/>
      <geometry>
        <mesh filename="package://intera_tools_description/meshes/electric_gripper/electric_gripper_base.DAE"/>
      </geometry>
    </visual>
    <collision>
      <origin rpy="-1.57079632679 3.14159265359 0" xyz="0.004 0.0 0.025"/>
      <geometry>
        <cylinder length="0.1" radius="0.029"/>
      </geometry>
      <material name="darkred">
        <color rgba=".5 .1 .1 1"/>
      </material>
    </collision>
    <inertial>
      <origin rpy="-1.57079632679 3.14159265359 0" xyz="0.0 0.0 0.0"/>
      <mass value="2e-06"/>
      <inertia ixx="1.1e-09" ixy="0" ixz="0" iyy="1.1e-09" iyz="0" izz="1.1e-09"/>
    </inertial>
  </link>
  <!-- Connector Plate Joint -->
  <joint name="right_connector_plate_base_joint" type="fixed">
    <origin rpy="0 0 0" xyz="0 0 0.0018"/>
    <parent link="right_gripper_base"/>
    <child link="right_connector_plate_base"/>
  </joint>
  <link name="right_connector_plate_base">
    <inertial>
      <origin rpy="0 0 0" xyz="0 0 0"/>
      <mass value="0.0"/>
      <inertia ixx="6.9922E-05" ixy="6.1026E-08" ixz="-1.7042E-06" iyy="6.8188E-05" iyz="-1.6118E-08" izz="0.00012392"/>
    </inertial>
    <visual>
      <origin rpy="0 0 0" xyz="0 0 0"/>
      <geometry>
        <mesh filename="package://intera_tools_description/meshes/connector_plate/connector_plate.STL"/>
      </geometry>
      <material name="black">
        <color rgba="0.05 0.05 0.05 1"/>
      </material>
    </visual>
    <collision>
      <origin rpy="0 0 0" xyz="0 0 0.0135"/>
      <geometry>
        <cylinder length="0.0302" radius="0.04"/>
      </geometry>
      <material name="darkred">
        <color rgba=".5 .1 .1 1"/>
      </material>
    </collision>
  </link>
  <gazebo reference="right_connector_plate_base">
    <material>Gazebo/FlatBlack</material>
  </gazebo>
  <link name="right_connector_plate_mount"/>
  <joint name="right_connector_plate_mount_joint" type="fixed">
    <origin rpy="0 0 0" xyz="0 0 0.0176"/>
    <parent link="right_connector_plate_base"/>
    <child link="right_connector_plate_mount"/>
  </joint>
  <!-- Electric Gripper Base joint -->
  <joint name="right_electric_gripper_base_joint" type="fixed">
    <origin rpy="0 0 0" xyz="0 0 0"/>
    <parent link="right_connector_plate_mount"/>
    <child link="right_electric_gripper_base"/>
  </joint>
  <link name="right_gripper_l_finger">
    <visual>
      <origin rpy="0 0 -3.14159265359" xyz="0 0 0"/>
      <geometry>
        <mesh filename="package://intera_tools_description/meshes/electric_gripper/fingers/standard_narrow.DAE"/>
      </geometry>
    </visual>
    <collision>
      <origin rpy="0 0 -3.14159265359" xyz="0 0.01725 0.04"/>
      <geometry>
        <box size="0.01 0.0135 0.075"/>
      </geometry>
    </collision>
    <collision>
      <origin rpy="0 0 -3.14159265359" xyz="-0.005 -0.003 0.0083"/>
      <geometry>
        <box size="0.01 0.05 0.017"/>
      </geometry>
    </collision>
    <inertial>
      <origin rpy="0 0 -3.14159265359" xyz="0 0 0"/>
      <mass value="0.001"/>
      <inertia ixx="0.01" ixy="0" ixz="0" iyy="0.01" iyz="0" izz="0.01"/>
    </inertial>
  </link>
  <gazebo reference="right_gripper_l_finger">
    <mu1>1000</mu1>
    <mu2>1000</mu2>
    <fdir1>0.0 0.0 1.0</fdir1>
    <kp>1e5</kp>
    <kd>1.0</kd>
  </gazebo>
  <link name="right_gripper_l_finger_tip">
    <visual>
      <origin rpy="0 0 3.14159265359" xyz="0 0 0"/>
      <geometry>
        <mesh filename="package://intera_tools_description/meshes/electric_gripper/fingers/basic_soft_tip.DAE"/>
      </geometry>
    </visual>
    <collision>
      <origin rpy="0 0 3.14159265359" xyz="0 -0.0045 -0.015"/>
      <geometry>
        <box size="0.016 0.007 0.037"/>
      </geometry>
    </collision>
    <inertial>
      <origin rpy="0 0 3.14159265359" xyz="0 0 0"/>
      <mass value="0.001"/>
      <inertia ixx="0.01" ixy="0" ixz="0" iyy="0.01" iyz="0" izz="0.01"/>
    </inertial>
  </link>
  <joint name="right_gripper_l_finger_tip_joint" type="fixed">
    <origin rpy="0 0 0" xyz="0.0 0.01725 0.075"/>
    <parent link="right_gripper_l_finger"/>
    <child link="right_gripper_l_finger_tip"/>
  </joint>
  <link name="right_gripper_r_finger">
    <visual>
      <origin rpy="0 0 -0.0" xyz="0 0 0"/>
      <geometry>
        <mesh filename="package://intera_tools_description/meshes/electric_gripper/fingers/standard_narrow.DAE"/>
      </geometry>
    </visual>
    <collision>
      <origin rpy="0 0 -0.0" xyz="0 -0.01725 0.04"/>
      <geometry>
        <box size="0.01 0.0135 0.075"/>
      </geometry>
    </collision>
    <collision>
      <origin rpy="0 0 -0.0" xyz="0.005 0.003 0.0083"/>
      <geometry>
        <box size="0.01 0.05 0.017"/>
      </geometry>
    </collision>
    <inertial>
      <origin rpy="0 0 -0.0" xyz="0 0 0"/>
      <mass value="0.001"/>
      <inertia ixx="0.01" ixy="0" ixz="0" iyy="0.01" iyz="0" izz="0.01"/>
    </inertial>
  </link>
  <gazebo reference="right_gripper_r_finger">
    <mu1>1000</mu1>
    <mu2>1000</mu2>
    <fdir1>0.0 0.0 1.0</fdir1>
    <kp>1e5</kp>
    <kd>1.0</kd>
  </gazebo>
  <link name="right_gripper_r_finger_tip">
    <visual>
      <origin rpy="0 0 0.0" xyz="0 0 0"/>
      <geometry>
        <mesh filename="package://intera_tools_description/meshes/electric_gripper/fingers/basic_soft_tip.DAE"/>
      </geometry>
    </visual>
    <collision>
      <origin rpy="0 0 0.0" xyz="0 0.0045 -0.015"/>
      <geometry>
        <box size="0.016 0.007 0.037"/>
      </geometry>
    </collision>
    <inertial>
      <origin rpy="0 0 0.0" xyz="0 0 0"/>
      <mass value="0.001"/>
      <inertia ixx="0.01" ixy="0" ixz="0" iyy="0.01" iyz="0" izz="0.01"/>
    </inertial>
  </link>
  <joint name="right_gripper_r_finger_tip_joint" type="fixed">
    <origin rpy="0 0 0" xyz="0.0 -0.01725 0.075"/>
    <parent link="right_gripper_r_finger"/>
    <child link="right_gripper_r_finger_tip"/>
  </joint>
  <joint name="right_gripper_base_joint" type="fixed">
    <origin rpy="0 0 0" xyz="0 0 -0.005"/>
    <parent link="right_hand"/>
    <child link="right_gripper_base"/>
  </joint>
  <joint name="right_gripper_tip_joint" type="fixed">
    <origin rpy="0 0 0" xyz="0 0 0.14062"/>
    <parent link="right_gripper_base"/>
    <child link="right_gripper_tip"/>
  </joint>
  <!-- Electric Gripper Tip link -->
  <link name="right_gripper_tip">
    <inertial>
      <origin rpy="0 0 0" xyz="0 0 0"/>
      <mass value="2e-06"/>
      <inertia ixx="1.1e-09" ixy="0" ixz="0" iyy="1.1e-09" iyz="0" izz="1.1e-09"/>
    </inertial>
  </link>
  <joint name="right_gripper_l_finger_joint" type="prismatic">
    <origin rpy="0 0 0" xyz="0.003 -0.0015 0.04552"/>
    <axis xyz="0 1 0"/>
    <parent link="right_electric_gripper_base"/>
    <child link="right_gripper_l_finger"/>
    <limit effort="20.0" lower="0.0" upper="0.020833" velocity="5.0"/>
    <dynamics damping="100.0" friction="500.0"/>
  </joint>
  <joint name="right_gripper_r_finger_joint" type="prismatic">
    <origin rpy="0 0 0" xyz="0.003 0.0015 0.04552"/>
    <axis xyz="0 1 0"/>
    <parent link="right_electric_gripper_base"/>
    <child link="right_gripper_r_finger"/>
    <limit effort="20.0" lower="-0.020833" upper="0.0" velocity="5.0"/>
    <mimic joint="right_gripper_l_finger_joint" multiplier="-1.0"/>
    <dynamics damping="100.0" friction="500.0"/>
  </joint>
  <transmission name="gripper_right1">
    <type>transmission_interface/SimpleTransmission</type>
    <joint name="right_gripper_r_finger_joint">
      <hardwareInterface>hardware_interface/EffortJointInterface</hardwareInterface>
    </joint>
    <actuator name="gripper_right1_motor1">
      <hardwareInterface>hardware_interface/EffortJointInterface</hardwareInterface>
      <mechanicalReduction>1</mechanicalReduction>
    </actuator>
  </transmission>
  <transmission name="gripper_right2">
    <type>transmission_interface/SimpleTransmission</type>
    <joint name="right_gripper_l_finger_joint">
      <hardwareInterface>hardware_interface/EffortJointInterface</hardwareInterface>
    </joint>
    <actuator name="gripper_right1_motor2">
      <hardwareInterface>hardware_interface/EffortJointInterface</hardwareInterface>
      <mechanicalReduction>1</mechanicalReduction>
    </actuator>
  </transmission>
  <gazebo reference="right_gripper_r_finger_joint">
    <implicitSpringDamper>1</implicitSpringDamper>
  </gazebo>
  <gazebo reference="right_gripper_l_finger_joint">
    <implicitSpringDamper>1</implicitSpringDamper>
  </gazebo>
  <!-- ros_control plugin -->
  <gazebo>
    <plugin filename="libsawyer_gazebo_ros_control.so" name="sawyer_ros_control">
      <robotNamespace>/robot</robotNamespace>
      <robotSimType>sawyer_gazebo/SawyerRobotHWSim</robotSimType>
      <controlPeriod>0.001</controlPeriod>
      <eStopTopic>sim_estop</eStopTopic>
    </plugin>
  </gazebo>
  <link name="world"/>
  <joint name="fixed" type="fixed">
    <parent link="world"/>
    <child link="base"/>
  </joint>
  <gazebo reference="torso">
    <self_collide>true</self_collide>
  </gazebo>
  <gazebo reference="head_pan">
    <implicitSpringDamper>1</implicitSpringDamper>
    <provideFeedback>true</provideFeedback>
  </gazebo>
  <gazebo reference="right_j0">
    <implicitSpringDamper>1</implicitSpringDamper>
    <provideFeedback>true</provideFeedback>
  </gazebo>
  <gazebo reference="right_j1">
    <implicitSpringDamper>1</implicitSpringDamper>
    <provideFeedback>true</provideFeedback>
  </gazebo>
  <gazebo reference="right_j2">
    <implicitSpringDamper>1</implicitSpringDamper>
    <provideFeedback>true</provideFeedback>
  </gazebo>
  <gazebo reference="right_j3">
    <implicitSpringDamper>1</implicitSpringDamper>
    <provideFeedback>true</provideFeedback>
  </gazebo>
  <gazebo reference="right_j4">
    <implicitSpringDamper>1</implicitSpringDamper>
    <provideFeedback>true</provideFeedback>
  </gazebo>
  <gazebo reference="right_j5">
    <implicitSpringDamper>1</implicitSpringDamper>
    <provideFeedback>true</provideFeedback>
  </gazebo>
  <gazebo reference="right_j6">
    <implicitSpringDamper>1</implicitSpringDamper>
    <provideFeedback>true</provideFeedback>
  </gazebo>
  <joint name="head_camera_optical_joint" type="fixed">
    <origin rpy="-3.14159265359 -1.57079632679 -1.57079632679" xyz="0 0 0"/>
    <parent link="head_camera"/>
    <child link="head_camera_optical"/>
  </joint>
  <link name="head_camera_optical"/>
  <gazebo reference="head_camera_optical">
    <sensor name="head_camera" type="camera">
      <update_rate>10</update_rate>
      <camera name="head_camera">
        <horizontal_fov>2.00787026</horizontal_fov>
        <image>
          <width>1280</width>
          <height>800</height>
          <format>R8G8B8</format>
        </image>
        <clip>
          <near>0.1</near>
          <far>50</far>
        </clip>
        <!-- Uncomment to add image Distortion -->
        <!-- distortion>
          <k1>0.6545419633392568</k1>
          <k2>0.012904541485280972</k2>
          <k3>-0.012279942338550547</k3>
          <p1>-0.00036475699823703154</p1>
          <p2>3.334461262764956e-05</p2>
          <center>677.8808657338167 382.02964533321426</center>
        </distortion -->
      </camera>
      <!-- Uncomment to visualize image inside Gazebo -->
      <!-- visualize>true</visualize -->
      <plugin filename="libgazebo_ros_camera.so" name="camera_controller">
        <alwaysOn>true</alwaysOn>
        <updateRate>10</updateRate>
        <cameraName>head_camera</cameraName>
        <imageTopicName>/io/internal_camera/head_camera/image_raw</imageTopicName>
        <cameraInfoTopicName>/io/internal_camera/head_camera/camera_info</cameraInfoTopicName>
        <frameName>head_camera</frameName>
        <focalLength>407.391526</focalLength>
        <!-- Uncomment to add image Distortion params to camera_info topic -->
        <!-- distortionK1>0.6545419633392568</distortionK1>
        <distortionK2>0.012904541485280972</distortionK2>
        <distortionK3>-0.012279942338550547</distortionK3>
        <distortionT1>-0.00036475699823703154</distortionT1>
        <distortionT2>3.334461262764956e-05</distortionT2>
        <Cx>677.8808657338167</Cx>
        <Cy>382.02964533321426</Cy -->
      </plugin>
    </sensor>
  </gazebo>
  <joint name="right_hand_camera_optical_joint" type="fixed">
    <origin rpy="-3.14159265359 -1.57079632679 -1.57079632679" xyz="0 0 0"/>
    <parent link="right_hand_camera"/>
    <child link="right_hand_camera_optical"/>
  </joint>
  <link name="right_hand_camera_optical"/>
  <gazebo reference="right_hand_camera_optical">
    <sensor name="right_hand_camera" type="camera">
      <update_rate>10.0</update_rate>
      <camera name="right_hand_camera">
        <horizontal_fov>1.0992892</horizontal_fov>
        <image>
          <width>752</width>
          <height>480</height>
          <format>L8</format>
        </image>
        <clip>
          <near>0.02</near>
          <far>10</far>
        </clip>
        <!-- Uncomment to add image Distortion -->
        <!-- distortion>
          <k1>-0.442</k1>
          <k2>0.273</k2>
          <k3>-0.123</k3>
          <p1>0.0</p1>
          <p2>0.0</p2>
          <center>365.734985 237.988998</center>
        </distortion -->
      </camera>
      <!-- Uncomment to visualize image inside Gazebo -->
      <!-- visualize>true</visualize -->
      <plugin filename="libgazebo_ros_camera.so" name="camera_controller">
        <alwaysOn>true</alwaysOn>
        <updateRate>10.0</updateRate>
        <cameraName>right_hand_camera</cameraName>
        <imageTopicName>/io/internal_camera/right_hand_camera/image_raw</imageTopicName>
        <cameraInfoTopicName>/io/internal_camera/right_hand_camera/camera_info</cameraInfoTopicName>
        <frameName>right_hand_camera</frameName>
        <focalLength>613.760435</focalLength>
        <!-- Uncomment to add image Distortion params to camera_info topic -->
        <!-- distortionK1>-0.442</distortionK1>
        <distortionK2>0.273</distortionK2>
        <distortionK3>-0.123</distortionK3>
        <distortionT1>0.0</distortionT1>
        <distortionT2>0.0</distortionT2>
        <Cx>365.734985</Cx>
        <Cy>237.988998</Cy -->
      </plugin>
    </sensor>
  </gazebo>
  <gazebo reference="screen">
    <visual>
      <plugin filename="libgazebo_ros_video.so" name="screen_video_controller">
        <height>600</height>
        <width>1024</width>
        <topicName>/robot/head_display</topicName>
        <robotNamespace>/robot</robotNamespace>
      </plugin>
    </visual>
  </gazebo>
  <!-- Transmissions -->
  <!-- Right Arm -->
  <transmission name="right_tran0">
    <type>transmission_interface/SimpleTransmission</type>
    <joint name="right_j0">
      <hardwareInterface>hardware_interface/EffortJointInterface</hardwareInterface>
    </joint>
    <actuator name="right_motor0">
      <hardwareInterface>hardware_interface/EffortJointInterface</hardwareInterface>
      <mechanicalReduction>1</mechanicalReduction>
    </actuator>
  </transmission>
  <transmission name="right_tran1">
    <type>transmission_interface/SimpleTransmission</type>
    <joint name="right_j1">
      <hardwareInterface>hardware_interface/EffortJointInterface</hardwareInterface>
    </joint>
    <actuator name="right_motor1">
      <hardwareInterface>hardware_interface/EffortJointInterface</hardwareInterface>
      <mechanicalReduction>1</mechanicalReduction>
    </actuator>
  </transmission>
  <transmission name="right_tran2">
    <type>transmission_interface/SimpleTransmission</type>
    <joint name="right_j2">
      <hardwareInterface>hardware_interface/EffortJointInterface</hardwareInterface>
    </joint>
    <actuator name="right_motor2">
      <hardwareInterface>hardware_interface/EffortJointInterface</hardwareInterface>
      <mechanicalReduction>1</mechanicalReduction>
    </actuator>
  </transmission>
  <transmission name="right_tran3">
    <type>transmission_interface/SimpleTransmission</type>
    <joint name="right_j3">
      <hardwareInterface>hardware_interface/EffortJointInterface</hardwareInterface>
    </joint>
    <actuator name="right_motor3">
      <hardwareInterface>hardware_interface/EffortJointInterface</hardwareInterface>
      <mechanicalReduction>1</mechanicalReduction>
    </actuator>
  </transmission>
  <transmission name="right_tran4">
    <type>transmission_interface/SimpleTransmission</type>
    <joint name="right_j4">
      <hardwareInterface>hardware_interface/EffortJointInterface</hardwareInterface>
    </joint>
    <actuator name="right_motor4">
      <hardwareInterface>hardware_interface/EffortJointInterface</hardwareInterface>
      <mechanicalReduction>1</mechanicalReduction>
    </actuator>
  </transmission>
  <transmission name="right_tran5">
    <type>transmission_interface/SimpleTransmission</type>
    <joint name="right_j5">
      <hardwareInterface>hardware_interface/EffortJointInterface</hardwareInterface>
    </joint>
    <actuator name="right_motor5">
      <hardwareInterface>hardware_interface/EffortJointInterface</hardwareInterface>
      <mechanicalReduction>1</mechanicalReduction>
    </actuator>
  </transmission>
  <transmission name="right_tran6">
    <type>transmission_interface/SimpleTransmission</type>
    <joint name="right_j6">
      <hardwareInterface>hardware_interface/EffortJointInterface</hardwareInterface>
    </joint>
    <actuator name="right_motor6">
      <hardwareInterface>hardware_interface/EffortJointInterface</hardwareInterface>
      <mechanicalReduction>1</mechanicalReduction>
    </actuator>
  </transmission>
  <!-- Head -->
  <transmission name="head0">
    <type>transmission_interface/SimpleTransmission</type>
    <joint name="head_pan">
      <hardwareInterface>hardware_interface/EffortJointInterface</hardwareInterface>
    </joint>
    <actuator name="head_motor0">
      <hardwareInterface>hardware_interface/EffortJointInterface</hardwareInterface>
      <mechanicalReduction>1</mechanicalReduction>
    </actuator>
  </transmission>
  <!-- link form ridgeback to sawyer mounting plate  -->
  <link name="sawyer_mount_link">
    <inertial>
      <origin rpy="0 0 0" xyz="0 0 0.5"/>
      <mass value="1"/>
      <inertia ixx="0.004086" ixy="0" ixz="0" iyy="0.004086" iyz="0" izz="0.008065"/>
    </inertial>
    <visual>
      <origin rpy="0 0 0" xyz="0 0 0"/>
      <geometry>
        <cylinder length="0.0254" radius="0.127"/>
      </geometry>
      <material name="white">
        <color rgba="1.0 1.0 1.0 1.0"/>
      </material>
    </visual>
    <collision>
      <origin rpy="0 0 0" xyz="0 0 0"/>
      <geometry>
        <cylinder length="0.0254" radius="0.127"/>
      </geometry>
    </collision>
  </link>
  <joint name="sawyer_mount_joint" type="fixed">
    <origin rpy="0 0 0" xyz="0.0 0.0 0.0"/>
    <parent link="mid_mount"/>
    <child link="sawyer_mount_link"/>
  </joint>
  <joint name="sawyer_base_joint" type="fixed">
    <origin rpy="0 0 0" xyz="0.0 0.0 0.0127"/>
    <parent link="sawyer_mount_link"/>
    <child link="world"/>
  </joint>
  <joint name="sawyer_world_joint" type="fixed">
    <origin rpy="0 0 0" xyz="0.0 0.0 0.0127"/>
    <parent link="world"/>
    <child link="base"/>
  </joint>
</robot>
